Workbook

Sheet cosn
B1: cosn calculator | I1: Helper tables to compute data for plots
A2: Beams for illumination can often be modelled quite well using a cosn(alpha) distribution. | Q2: LightTools apodization helper | U2: encircled energy helper
A3: I prefer cosn over Gaussian distributions for several reasons: | I3: alpha | J3: ="cos^"&TEXT(B15,"0.00") -> cos^1.00 | K3: ="FWHM "&TEXT(D16,"0.0")&"°" -> FWHM 16.0° | L3: ="I0/Phi "&TEXT(E18,"0.00")&" cd/lm" -> I0/Phi 20.00 cd/lm | M3: ="sigma "&TEXT(F19,"0.00")&"°" -> sigma 17.91° | O3: cos | Q3: cos^(n+1) | R3: analytical value for 1° interval | U3: ="1 - cos^"&TEXT(B15+1,"0.00") -> 1 - cos^2.00
A4: a) zero at 90°, even for wide beams | I4: -90 | J4: =$O4^$B$15 -> 6.1257423e-17 | K4: =$O4^D$15 -> 0 | L4: =$O4^E$15 -> 0 | M4: =EXP(-0.5*(I4^2)/(F$19^2)) -> 3.2856574e-06 | O4: =COS(I4*PI()/180) -> 6.1257423e-17 | Q4: =$O4^($B$15+1) -> 3.7524718e-33 | R4: =+(Q5-Q4)/(($B$15+1)*(O5-O4)) -> 0.0087262032
A5: b) easy to integrate analytically | I5: -89 | J5: =$O5^$B$15 -> 0.017452406 | K5: =$O5^D$15 -> 2.4445744e-125 | L5: =$O5^E$15 -> 6.6553065e-220 | M5: =EXP(-0.5*(I5^2)/(F$19^2)) -> 4.3430833e-06 | O5: =COS(I5*PI()/180) -> 0.017452406 | Q5: =$O5^($B$15+1) -> 0.00030458649 | R5: =+(Q6-Q5)/(($B$15+1)*(O6-O5)) -> 0.026175952
A6: c) simple relation between peak intensity and flux | I6: -88 | J6: =$O6^$B$15 -> 0.034899497 | K6: =$O6^D$15 -> 5.2429946e-104 | L6: =$O6^E$15 -> 2.2000698e-182 | M6: =EXP(-0.5*(I6^2)/(F$19^2)) -> 5.7229522e-06 | O6: =COS(I6*PI()/180) -> 0.034899497 | Q6: =$O6^($B$15+1) -> 0.0012179749 | R6: =+(Q7-Q6)/(($B$15+1)*(O7-O6)) -> 0.043617726
A7: This worksheet is intended to make cosn easy to use for you, the optical designers. | I7: -87 | J7: =$O7^$B$15 -> 0.052335956 | K7: =$O7^D$15 -> 1.5579816e-91 | L7: =$O7^E$15 -> 1.909326e-160 | M7: =EXP(-0.5*(I7^2)/(F$19^2)) -> 7.5177548e-06 | O7: =COS(I7*PI()/180) -> 0.052335956 | Q7: =$O7^($B$15+1) -> 0.0027390523 | R7: =+(Q8-Q7)/(($B$15+1)*(O8-O7)) -> 0.061046215
I8: -86 | J8: =$O8^$B$15 -> 0.069756474 | K8: =$O8^D$15 -> 1.0886472e-82 | L8: =$O8^E$15 -> 6.8700553e-145 | M8: =EXP(-0.5*(I8^2)/(F$19^2)) -> 9.8446952e-06 | O8: =COS(I8*PI()/180) -> 0.069756474 | Q8: =$O8^($B$15+1) -> 0.0048659656 | R8: =+(Q9-Q8)/(($B$15+1)*(O9-O8)) -> 0.078456108
A9: Input is yellow | B9: Output is green | I9: -85 | J9: =$O9^$B$15 -> 0.087155743 | K9: =$O9^D$15 -> 7.7892403e-76 | L9: =$O9^E$15 -> 7.8229937e-133 | M9: =EXP(-0.5*(I9^2)/(F$19^2)) -> 1.2851756e-05 | O9: =COS(I9*PI()/180) -> 0.087155743 | Q9: =$O9^($B$15+1) -> 0.0075961235 | R9: =+(Q10-Q9)/(($B$15+1)*(O10-O9)) -> 0.095842103
A10: This software is public domain, provided as-is without any warranty, under the Unlicense. See https://unlicense.org | I10: -84 | J10: =$O10^$B$15 -> 0.10452846 | K10: =$O10^D$15 -> 3.0648779e-70 | L10: =$O10^E$15 -> 5.4218325e-123 | M10: =EXP(-0.5*(I10^2)/(F$19^2)) -> 1.6725101e-05 | O10: =COS(I10*PI()/180) -> 0.10452846 | Q10: =$O10^($B$15+1) -> 0.0109262 | R10: =+(Q11-Q10)/(($B$15+1)*(O11-O10)) -> 0.1131989
A11: Comments are welcome: Please send to the author, Julius Muschaweck, julius@jmoptics.de | I11: -83 | J11: =$O11^$B$15 -> 0.12186934 | K11: =$O11^D$15 -> 1.625769e-65 | L11: =$O11^E$15 -> 1.1071768e-114 | M11: =EXP(-0.5*(I11^2)/(F$19^2)) -> 2.169807e-05 | O11: =COS(I11*PI()/180) -> 0.12186934 | Q11: =$O11^($B$15+1) -> 0.014852137 | R11: =+(Q12-Q11)/(($B$15+1)*(O12-O11)) -> 0.13052122
I12: -82 | J12: =$O12^$B$15 -> 0.1391731 | K12: =$O12^D$15 -> 1.9855386e-61 | L12: =$O12^E$15 -> 1.7077728e-107 | M12: =EXP(-0.5*(I12^2)/(F$19^2)) -> 2.8062059e-05 | O12: =COS(I12*PI()/180) -> 0.1391731 | Q12: =$O12^($B$15+1) -> 0.019369152 | R12: =+(Q13-Q12)/(($B$15+1)*(O13-O12)) -> 0.14780378
I13: -81 | J13: =$O13^$B$15 -> 0.15643447 | K13: =$O13^D$15 -> 7.8850241e-58 | L13: =$O13^E$15 -> 3.6517095e-101 | M13: =EXP(-0.5*(I13^2)/(F$19^2)) -> 3.6179624e-05 | O13: =COS(I13*PI()/180) -> 0.15643447 | Q13: =$O13^($B$15+1) -> 0.024471742 | R13: =+(Q14-Q13)/(($B$15+1)*(O14-O13)) -> 0.16504132
B14: Main (from n) | D14: From FWHM | E14: From I0/phi | F14: Gaussian s | I14: -80 | J14: =$O14^$B$15 -> 0.17364818 | K14: =$O14^D$15 -> 1.2888539e-54 | L14: =$O14^E$15 -> 1.6386001e-95 | M14: =EXP(-0.5*(I14^2)/(F$19^2)) -> 4.6500181e-05 | O14: =COS(I14*PI()/180) -> 0.17364818 | Q14: =$O14^($B$15+1) -> 0.03015369 | R14: =+(Q15-Q14)/(($B$15+1)*(O15-O14)) -> 0.18222859
A15: n | B15: 1 | D15: =LOG(0.5)/LOG(COS(D16/2*PI()/180)) -> 70.876873 | E15: =+(2*PI()*E18-1) -> 124.66371 | F15: =LOG(0.5)/LOG(COS(F16/2*PI()/180)) -> 9.9999387 | I15: -79 | J15: =$O15^$B$15 -> 0.190809 | K15: =$O15^D$15 -> 1.0258785e-51 | L15: =$O15^E$15 -> 2.0738904e-90 | M15: =EXP(-0.5*(I15^2)/(F$19^2)) -> 5.957874e-05 | O15: =COS(I15*PI()/180) -> 0.190809 | Q15: =$O15^($B$15+1) -> 0.036408073 | R15: =+(Q16-Q15)/(($B$15+1)*(O16-O15)) -> 0.19936034
A16: FWHM | B16: =2*ACOS(0.5^(1/(B15+0.0000000001)))*180/PI() -> 120 | C16: ° | D16: 16 | E16: =2*ACOS(0.5^(1/(E15+0.0000000001)))*180/PI() -> 12.072795 | F16: =2*F19*SQRT(LN(4)) -> 42.174827 | G16: ° | I16: -78 | J16: =$O16^$B$15 -> 0.20791169 | K16: =$O16^D$15 -> 4.5018433e-49 | L16: =$O16^E$15 -> 9.2099425e-86 | M16: =EXP(-0.5*(I16^2)/(F$19^2)) -> 7.6098145e-05 | O16: =COS(I16*PI()/180) -> 0.20791169 | Q16: =$O16^($B$15+1) -> 0.043227271 | R16: =+(Q17-Q16)/(($B$15+1)*(O17-O16)) -> 0.21643137
A17: FW0.1M | B17: =2*ACOS(0.1^(1/(B15+0.0000000001)))*180/PI() -> 168.52166 | C17: ° | D17: =2*ACOS(0.1^(1/(D15+0.0000000001)))*180/PI() -> 29.051543 | E17: =2*ACOS(0.1^(1/(E15+0.0000000001)))*180/PI() -> 21.956732 | F17: =2*F19*SQRT(2*LN(1/0.1)) -> 76.868503 | G17: ° | I17: -77 | J17: =$O17^$B$15 -> 0.22495105 | K17: =$O17^D$15 -> 1.1968122e-46 | L17: =$O17^E$15 -> 1.6939202e-81 | M17: =EXP(-0.5*(I17^2)/(F$19^2)) -> 9.6895343e-05 | O17: =COS(I17*PI()/180) -> 0.22495105 | Q17: =$O17^($B$15+1) -> 0.050602977 | R17: =+(Q18-Q17)/(($B$15+1)*(O18-O17)) -> 0.23343647
A18: I0 / Phi | B18: =+(B15+1)/(2*PI()) -> 0.31830989 | C18: cd/lm | D18: =+(D15+1)/(2*PI()) -> 11.43956 | E18: 20 | F18: ="≈ "&TEXT((F15+1)/(2*PI()),"0.00") -> ≈ 1.75 | G18: cd/lm | I18: -76 | J18: =$O18^$B$15 -> 0.2419219 | K18: =$O18^D$15 -> 2.0740727e-44 | L18: =$O18^E$15 -> 1.4677881e-77 | M18: =EXP(-0.5*(I18^2)/(F$19^2)) -> 0.00012299227 | O18: =COS(I18*PI()/180) -> 0.2419219 | Q18: =$O18^($B$15+1) -> 0.058526204 | R18: =+(Q19-Q18)/(($B$15+1)*(O19-O18)) -> 0.25037047
A19: Gaussian sigma | B19: =IF(B16<=60,0.5*B16/SQRT(LN(4)),"FWHM>60") -> FWHM>60 | C19: ° | D19: =IF(D16<=60,0.5*D16/SQRT(LN(4)),"FWHM>60") -> 6.7945744 | E19: =IF(E16<=60,0.5*E16/SQRT(LN(4)),"FWHM>60") -> 5.1268438 | F19: 17.91 | G19: ° | I19: -75 | J19: =$O19^$B$15 -> 0.25881905 | K19: =$O19^D$15 -> 2.4831821e-42 | L19: =$O19^E$15 -> 6.636431e-74 | M19: =EXP(-0.5*(I19^2)/(F$19^2)) -> 0.00015563197 | O19: =COS(I19*PI()/180) -> 0.25881905 | Q19: =$O19^($B$15+1) -> 0.066987298 | R19: =+(Q20-Q19)/(($B$15+1)*(O20-O19)) -> 0.2672282
A20: I0/Phi of FWHM trunc'd Lambert | B20: =1/(PI()*(SIN(RADIANS(B16/2)))^2) -> 0.42441318 | C20: cd/lm | D20: =1/(PI()*(SIN(RADIANS(D16/2)))^2) -> 16.433858 | E20: =1/(PI()*(SIN(RADIANS(E16/2)))^2) -> 28.783739 | F20: =1/(PI()*(SIN(RADIANS(F16/2)))^2) -> 2.4589374 | G20: cd/lm | I20: -74 | J20: =$O20^$B$15 -> 0.27563736 | K20: =$O20^D$15 -> 2.1523505e-40 | L20: =$O20^E$15 -> 1.7000835e-70 | M20: =EXP(-0.5*(I20^2)/(F$19^2)) -> 0.0001963206 | O20: =COS(I20*PI()/180) -> 0.27563736 | Q20: =$O20^($B$15+1) -> 0.075975952 | R20: =+(Q21-Q20)/(($B$15+1)*(O21-O20)) -> 0.28400453
I21: -73 | J21: =$O21^$B$15 -> 0.2923717 | K21: =$O21^D$15 -> 1.4033535e-38 | L21: =$O21^E$15 -> 2.6394909e-67 | M21: =EXP(-0.5*(I21^2)/(F$19^2)) -> 0.00024687609 | O21: =COS(I21*PI()/180) -> 0.2923717 | Q21: =$O21^($B$15+1) -> 0.085481214 | R21: =+(Q22-Q21)/(($B$15+1)*(O22-O21)) -> 0.30069435
A22: (up to about 60° FWHM, there is negligible difference between Gaussian and cosn) | I22: -72 | J22: =$O22^$B$15 -> 0.30901699 | K22: =$O22^D$15 -> 7.1046871e-37 | L22: =$O22^E$15 -> 2.6261003e-64 | M22: =EXP(-0.5*(I22^2)/(F$19^2)) -> 0.00030948404 | O22: =COS(I22*PI()/180) -> 0.30901699 | Q22: =$O22^($B$15+1) -> 0.095491503 | R22: =+(Q23-Q22)/(($B$15+1)*(O23-O22)) -> 0.31729257
I23: -71 | J23: =$O23^$B$15 -> 0.32556815 | K23: =$O23^D$15 -> 2.8680271e-35 | L23: =$O23^E$15 -> 1.7544267e-61 | M23: =EXP(-0.5*(I23^2)/(F$19^2)) -> 0.0003867618 | O23: =COS(I23*PI()/180) -> 0.32556815 | Q23: =$O23^($B$15+1) -> 0.10599462 | R23: =+(Q24-Q23)/(($B$15+1)*(O24-O23)) -> 0.33379415
I24: -70 | J24: =$O24^$B$15 -> 0.34202014 | K24: =$O24^D$15 -> 9.4414909e-34 | L24: =$O24^E$15 -> 8.1875909e-59 | M24: =EXP(-0.5*(I24^2)/(F$19^2)) -> 0.00048183125 | O24: =COS(I24*PI()/180) -> 0.34202014 | Q24: =$O24^($B$15+1) -> 0.11697778 | R24: =+(Q25-Q24)/(($B$15+1)*(O25-O24)) -> 0.35019405
I25: -69 | J25: =$O25^$B$15 -> 0.35836795 | K25: =$O25^D$15 -> 2.5837158e-32 | L25: =$O25^E$15 -> 2.7607151e-56 | M25: =EXP(-0.5*(I25^2)/(F$19^2)) -> 0.00059840117 | O25: =COS(I25*PI()/180) -> 0.35836795 | Q25: =$O25^($B$15+1) -> 0.12842759 | R25: =+(Q26-Q25)/(($B$15+1)*(O26-O25)) -> 0.36648727
I26: -68 | J26: =$O26^$B$15 -> 0.37460659 | K26: =$O26^D$15 -> 5.9752919e-31 | L26: =$O26^E$15 -> 6.9235862e-54 | M26: =EXP(-0.5*(I26^2)/(F$19^2)) -> 0.00074085971 | O26: =COS(I26*PI()/180) -> 0.37460659 | Q26: =$O26^($B$15+1) -> 0.1403301 | R26: =+(Q27-Q26)/(($B$15+1)*(O27-O26)) -> 0.38266886
I27: -67 | J27: =$O27^$B$15 -> 0.39073113 | K27: =$O27^D$15 -> 1.1846493e-29 | L27: =$O27^E$15 -> 1.3243427e-51 | M27: =EXP(-0.5*(I27^2)/(F$19^2)) -> 0.00091437766 | O27: =COS(I27*PI()/180) -> 0.39073113 | Q27: =$O27^($B$15+1) -> 0.15267081 | R27: =+(Q28-Q27)/(($B$15+1)*(O28-O27)) -> 0.39873389
I28: -66 | J28: =$O28^$B$15 -> 0.40673664 | K28: =$O28^D$15 -> 2.0386774e-28 | L28: =$O28^E$15 -> 1.9749133e-49 | M28: =EXP(-0.5*(I28^2)/(F$19^2)) -> 0.0011250228 | O28: =COS(I28*PI()/180) -> 0.40673664 | Q28: =$O28^($B$15+1) -> 0.1654347 | R28: =+(Q29-Q28)/(($B$15+1)*(O29-O28)) -> 0.41467745
I29: -65 | J29: =$O29^$B$15 -> 0.42261826 | K29: =$O29^D$15 -> 3.0788066e-27 | L29: =$O29^E$15 -> 2.3405813e-47 | M29: =EXP(-0.5*(I29^2)/(F$19^2)) -> 0.0013798857 | O29: =COS(I29*PI()/180) -> 0.42261826 | Q29: =$O29^($B$15+1) -> 0.1786062 | R29: =+(Q30-Q29)/(($B$15+1)*(O30-O29)) -> 0.4304947
I30: -64 | J30: =$O30^$B$15 -> 0.43837115 | K30: =$O30^D$15 -> 4.1198206e-26 | L30: =$O30^E$15 -> 2.2422888e-45 | M30: =EXP(-0.5*(I30^2)/(F$19^2)) -> 0.0016872171 | O30: =COS(I30*PI()/180) -> 0.43837115 | Q30: =$O30^($B$15+1) -> 0.19216926 | R30: =+(Q31-Q30)/(($B$15+1)*(O31-O30)) -> 0.44618082
I31: -63 | J31: =$O31^$B$15 -> 0.4539905 | K31: =$O31^D$15 -> 4.926599e-25 | L31: =$O31^E$15 -> 1.7627011e-43 | M31: =EXP(-0.5*(I31^2)/(F$19^2)) -> 0.0020565767 | O31: =COS(I31*PI()/180) -> 0.4539905 | Q31: =$O31^($B$15+1) -> 0.20610737 | R31: =+(Q32-Q31)/(($B$15+1)*(O32-O31)) -> 0.46173103
I32: -62 | J32: =$O32^$B$15 -> 0.46947156 | K32: =$O32^D$15 -> 5.3050994e-24 | L32: =$O32^E$15 -> 1.1523838e-41 | M32: =EXP(-0.5*(I32^2)/(F$19^2)) -> 0.0024989925 | O32: =COS(I32*PI()/180) -> 0.46947156 | Q32: =$O32^($B$15+1) -> 0.22040355 | R32: =+(Q33-Q32)/(($B$15+1)*(O33-O32)) -> 0.47714059
I33: -61 | J33: =$O33^$B$15 -> 0.48480962 | K33: =$O33^D$15 -> 5.1793116e-23 | L33: =$O33^E$15 -> 6.3408007e-40 | M33: =EXP(-0.5*(I33^2)/(F$19^2)) -> 0.0030271299 | O33: =COS(I33*PI()/180) -> 0.48480962 | Q33: =$O33^($B$15+1) -> 0.23504037 | R33: =+(Q34-Q33)/(($B$15+1)*(O34-O33)) -> 0.49240481
I34: -60 | J34: =$O34^$B$15 -> 0.5 | K34: =$O34^D$15 -> 4.6124888e-22 | L34: =$O34^E$15 -> 2.9681448e-38 | M34: =EXP(-0.5*(I34^2)/(F$19^2)) -> 0.0036554701 | O34: =COS(I34*PI()/180) -> 0.5 | Q34: =$O34^($B$15+1) -> 0.25 | R34: =+(Q35-Q34)/(($B$15+1)*(O35-O34)) -> 0.50751904
... I38: -56 | J38: =$O38^$B$15 -> 0.5591929 | K38: =$O38^D$15 -> 1.2822104e-18 | L38: =$O38^E$15 -> 3.3892209e-32 | M38: =EXP(-0.5*(I38^2)/(F$19^2)) -> 0.0075344712 | O38: =COS(I38*PI()/180) -> 0.5591929 | Q38: =$O38^($B$15+1) -> 0.3126967 | R38: =+(Q39-Q38)/(($B$15+1)*(O39-O38)) -> 0.56638467
I39: -55 | J39: =$O39^$B$15 -> 0.57357644 | K39: =$O39^D$15 -> 7.7572253e-18 | L39: =$O39^E$15 -> 8.0370548e-31 | M39: =EXP(-0.5*(I39^2)/(F$19^2)) -> 0.0089576762 | O39: =COS(I39*PI()/180) -> 0.57357644 | Q39: =$O39^($B$15+1) -> 0.32898993 | R39: =+(Q43-Q39)/(($B$15+1)*(O43-O39)) -> 0.58068084
I43: -54 | J43: =$O43^$B$15 -> 0.58778525 | K43: =$O43^D$15 -> 4.3948306e-17 | L43: =$O43^E$15 -> 1.6980325e-29 | M43: =EXP(-0.5*(I43^2)/(F$19^2)) -> 0.010616565 | O43: =COS(I43*PI()/180) -> 0.58778525 | Q43: =$O43^($B$15+1) -> 0.3454915 | R43: =+(Q44-Q43)/(($B$15+1)*(O44-O43)) -> 0.59480014
A44: In LightTools, cos^n distributions are now available both for scattering surfaces | I44: -53 | J44: =$O44^$B$15 -> 0.60181502 | K44: =$O44^D$15 -> 2.3389928e-16 | L44: =$O44^E$15 -> 3.2139812e-28 | M44: =EXP(-0.5*(I44^2)/(F$19^2)) -> 0.012543501 | O44: =COS(I44*PI()/180) -> 0.60181502 | Q44: =$O44^($B$15+1) -> 0.36218132 | R44: =+(Q45-Q44)/(($B$15+1)*(O45-O44)) -> 0.60873825
A45: and as source apodization. | I45: -52 | J45: =$O45^$B$15 -> 0.61566148 | K45: =$O45^D$15 -> 1.1727846e-15 | L45: =$O45^E$15 -> 5.4776003e-27 | M45: =EXP(-0.5*(I45^2)/(F$19^2)) -> 0.014774051 | O45: =COS(I45*PI()/180) -> 0.61566148 | Q45: =$O45^($B$15+1) -> 0.37903905 | R45: =+(Q46-Q45)/(($B$15+1)*(O46-O45)) -> 0.62249093
A46: If, however, cos^n is your target distribution in an optimization, that is not | I46: -51 | J46: =$O46^$B$15 -> 0.62932039 | K46: =$O46^D$15 -> 5.5547235e-15 | L46: =$O46^E$15 -> 8.4452723e-26 | M46: =EXP(-0.5*(I46^2)/(F$19^2)) -> 0.017347084 | O46: =COS(I46*PI()/180) -> 0.62932039 | Q46: =$O46^($B$15+1) -> 0.39604415 | R46: =+(Q47-Q46)/(($B$15+1)*(O47-O46)) -> 0.636054
...

Sheet LightTools slice merit function
A1: LightTools Slice merit function helper for
A2: ="n = "&FIXED(cosn!B15,2) -> n = 1.00 | B2: (this is the value in cell cosn!B15)
A3: 1. Set the intensity slices like this:
A5: Full Sphere
A6: Max. Angle 90°
A7: Bin resolution: 1°
A8: Symmetry: Rotational
A15: 2. Create a Slice Merit Function:
A16: Right click on the slices
A24: 3. In the new Slice Merit function:
A25: Select the Slice Data tab
A26: Select "Target" as Data to View
A27: Select the first field at -90°
A28: Copy and paste the content of
A29: the green fields below.
G36: n | H36: =cosn!B15 -> 1
G38: cos | H38: cos^(n+1)
A39: Angle | B39: Slice values | C39: direct cos^n | D39: difference | E39: ratio | F39: -90 | G39: =COS(RADIANS(F39)) -> 6.1257423e-17 | H39: =G39^($H$36+1) -> 3.7524718e-33
A40: -90 | B40: =(H40-H39)/(($H$36+1)*(G40-G39)) -> 0.0043632677 | C40: =COS(RADIANS(A40))^cosn!$B$15 -> 6.1257423e-17 | D40: =+B40-C40 -> 0.0043632677 | E40: =+B40/C40 -> 7.1228392e+13 | F40: -89.5 | G40: =COS(RADIANS(F40)) -> 0.0087265355 | H40: =G40^($H$36+1) -> 7.6152422e-05
A41: -89 | B41: =(H41-H40)/(($H$36+1)*(G41-G40)) -> 0.017451742 | C41: =COS(RADIANS(A41))^cosn!$B$15 -> 0.017452406 | D41: =+B41-C41 -> -6.6453416e-07 | E41: =+B41/C41 -> 0.99996192 | F41: -88.5 | G41: =COS(RADIANS(F41)) -> 0.026176948 | H41: =G41^($H$36+1) -> 0.00068523262
A42: -88 | B42: =(H42-H41)/(($H$36+1)*(G42-G41)) -> 0.034898168 | C42: =COS(RADIANS(A42))^cosn!$B$15 -> 0.034899497 | D42: =+B42-C42 -> -1.3288659e-06 | E42: =+B42/C42 -> 0.99996192 | F42: -87.5 | G42: =COS(RADIANS(F42)) -> 0.043619387 | H42: =G42^($H$36+1) -> 0.001902651
A43: -87 | B43: =(H43-H42)/(($H$36+1)*(G43-G42)) -> 0.052333963 | C43: =COS(RADIANS(A43))^cosn!$B$15 -> 0.052335956 | D43: =+B43-C43 -> -1.9927928e-06 | E43: =+B43/C43 -> 0.99996192 | F43: -86.5 | G43: =COS(RADIANS(F43)) -> 0.06104854 | H43: =G43^($H$36+1) -> 0.0037269242
A44: -86 | B44: =(H44-H43)/(($H$36+1)*(G44-G43)) -> 0.069753818 | C44: =COS(RADIANS(A44))^cosn!$B$15 -> 0.069756474 | D44: =+B44-C44 -> -2.6561128e-06 | E44: =+B44/C44 -> 0.99996192 | F44: -85.5 | G44: =COS(RADIANS(F44)) -> 0.078459096 | H44: =G44^($H$36+1) -> 0.0061558297
A45: -85 | B45: =(H45-H44)/(($H$36+1)*(G45-G44)) -> 0.087152424 | C45: =COS(RADIANS(A45))^cosn!$B$15 -> 0.087155743 | D45: =+B45-C45 -> -3.3186236e-06 | E45: =+B45/C45 -> 0.99996192 | F45: -84.5 | G45: =COS(RADIANS(F45)) -> 0.095845753 | H45: =G45^($H$36+1) -> 0.0091864083
A46: -84 | B46: =(H46-H45)/(($H$36+1)*(G46-G45)) -> 0.10452448 | C46: =COS(RADIANS(A46))^cosn!$B$15 -> 0.10452846 | D46: =+B46-C46 -> -3.9801236e-06 | E46: =+B46/C46 -> 0.99996192 | F46: -83.5 | G46: =COS(RADIANS(F46)) -> 0.11320321 | H46: =G46^($H$36+1) -> 0.012814968
A47: -83 | B47: =(H47-H46)/(($H$36+1)*(G47-G46)) -> 0.1218647 | C47: =COS(RADIANS(A47))^cosn!$B$15 -> 0.12186934 | D47: =+B47-C47 -> -4.6404112e-06 | E47: =+B47/C47 -> 0.99996192 | F47: -82.5 | G47: =COS(RADIANS(F47)) -> 0.13052619 | H47: =G47^($H$36+1) -> 0.017037087
A48: -82 | B48: =(H48-H47)/(($H$36+1)*(G48-G47)) -> 0.1391678 | C48: =COS(RADIANS(A48))^cosn!$B$15 -> 0.1391731 | D48: =+B48-C48 -> -5.2992852e-06 | E48: =+B48/C48 -> 0.99996192 | F48: -81.5 | G48: =COS(RADIANS(F48)) -> 0.14780941 | H48: =G48^($H$36+1) -> 0.021847622
A49: -81 | B49: =(H49-H48)/(($H$36+1)*(G49-G48)) -> 0.15642851 | C49: =COS(RADIANS(A49))^cosn!$B$15 -> 0.15643447 | D49: =+B49-C49 -> -5.9565451e-06 | E49: =+B49/C49 -> 0.99996192 | F49: -80.5 | G49: =COS(RADIANS(F49)) -> 0.16504761 | H49: =G49^($H$36+1) -> 0.027240712
A50: -80 | B50: =(H50-H49)/(($H$36+1)*(G50-G49)) -> 0.17364157 | C50: =COS(RADIANS(A50))^cosn!$B$15 -> 0.17364818 | D50: =+B50-C50 -> -6.6119905e-06 | E50: =+B50/C50 -> 0.99996192 | F50: -79.5 | G50: =COS(RADIANS(F50)) -> 0.18223553 | H50: =G50^($H$36+1) -> 0.033209787
A51: -79 | B51: =(H51-H50)/(($H$36+1)*(G51-G50)) -> 0.19080173 | C51: =COS(RADIANS(A51))^cosn!$B$15 -> 0.190809 | D51: =+B51-C51 -> -7.2654219e-06 | E51: =+B51/C51 -> 0.99996192 | F51: -78.5 | G51: =COS(RADIANS(F51)) -> 0.19936793 | H51: =G51^($H$36+1) -> 0.039747573
... A130: 0 | B130: =(H130-H129)/(($H$36+1)*(G130-G129)) -> 0.99998096 | C130: =COS(RADIANS(A130))^cosn!$B$15 -> 1 | D130: =+B130-C130 -> -1.9038468e-05 | E130: =+B130/C130 -> 0.99998096 | F130: 0 | G130: =COS(RADIANS(F130)) -> 1 | H130: =G130^($H$36+1) -> 1
A131: 1 | B131: =(H131-H132)/(($H$36+1)*(G131-G132)) -> 0.99980962 | C131: =COS(RADIANS(A131))^cosn!$B$15 -> 0.9998477 | D131: =+B131-C131 -> -3.8071137e-05 | E131: =+B131/C131 -> 0.99996192 | F131: 0.5 | G131: =COS(RADIANS(F131)) -> 0.99996192 | H131: =G131^($H$36+1) -> 0.99992385
A132: 2 | B132: =(H132-H133)/(($H$36+1)*(G132-G133)) -> 0.99935277 | C132: =COS(RADIANS(A132))^cosn!$B$15 -> 0.99939083 | D132: =+B132-C132 -> -3.805374e-05 | E132: =+B132/C132 -> 0.99996192 | F132: 1.5 | G132: =COS(RADIANS(F132)) -> 0.99965732 | H132: =G132^($H$36+1) -> 0.99931477
A133: 3 | B133: =(H133-H134)/(($H$36+1)*(G133-G134)) -> 0.99859151 | C133: =COS(RADIANS(A133))^cosn!$B$15 -> 0.99862953 | D133: =+B133-C133 -> -3.8024753e-05 | E133: =+B133/C133 -> 0.99996192 | F133: 2.5 | G133: =COS(RADIANS(F133)) -> 0.99904822 | H133: =G133^($H$36+1) -> 0.99809735
A134: 4 | B134: =(H134-H135)/(($H$36+1)*(G134-G135)) -> 0.99752607 | C134: =COS(RADIANS(A134))^cosn!$B$15 -> 0.99756405 | D134: =+B134-C134 -> -3.7984182e-05 | E134: =+B134/C134 -> 0.99996192 | F134: 3.5 | G134: =COS(RADIANS(F134)) -> 0.9981348 | H134: =G134^($H$36+1) -> 0.99627308
A135: 5 | B135: =(H135-H136)/(($H$36+1)*(G135-G136)) -> 0.99615677 | C135: =COS(RADIANS(A135))^cosn!$B$15 -> 0.9961947 | D135: =+B135-C135 -> -3.7932042e-05 | E135: =+B135/C135 -> 0.99996192 | F135: 4.5 | G135: =COS(RADIANS(F135)) -> 0.99691733 | H135: =G135^($H$36+1) -> 0.99384417
A136: 6 | B136: =(H136-H137)/(($H$36+1)*(G136-G137)) -> 0.99448403 | C136: =COS(RADIANS(A136))^cosn!$B$15 -> 0.9945219 | D136: =+B136-C136 -> -3.7868346e-05 | E136: =+B136/C136 -> 0.99996192 | F136: 5.5 | G136: =COS(RADIANS(F136)) -> 0.9953962 | H136: =G136^($H$36+1) -> 0.99081359
A137: 7 | B137: =(H137-H138)/(($H$36+1)*(G137-G138)) -> 0.99250836 | C137: =COS(RADIANS(A137))^cosn!$B$15 -> 0.99254615 | D137: =+B137-C137 -> -3.7793116e-05 | E137: =+B137/C137 -> 0.99996192 | F137: 6.5 | G137: =COS(RADIANS(F137)) -> 0.99357186 | H137: =G137^($H$36+1) -> 0.98718503
A138: 8 | B138: =(H138-H139)/(($H$36+1)*(G138-G139)) -> 0.99023036 | C138: =COS(RADIANS(A138))^cosn!$B$15 -> 0.99026807 | D138: =+B138-C138 -> -3.7706374e-05 | E138: =+B138/C138 -> 0.99996192 | F138: 7.5 | G138: =COS(RADIANS(F138)) -> 0.99144486 | H138: =G138^($H$36+1) -> 0.98296291
A139: 9 | B139: =(H139-H140)/(($H$36+1)*(G139-G140)) -> 0.98765073 | C139: =COS(RADIANS(A139))^cosn!$B$15 -> 0.98768834 | D139: =+B139-C139 -> -3.7608146e-05 | E139: =+B139/C139 -> 0.99996192 | F139: 8.5 | G139: =COS(RADIANS(F139)) -> 0.98901586 | H139: =G139^($H$36+1) -> 0.97815238
...

Sheet LightTools apodization file
A1: ## LightTools (R) apodization file, created from JMO's cos^n calculator
A2: ## using | B2: ="n = "&FIXED(cosn!B15,2) -> n = 1.00 | C2: ="FWHM = "&FIXED(cosn!B16,2)&"°" -> FWHM = 120.00° | D2: ="I/Phi = "&FIXED(cosn!B18,3)&" cd/lm" -> I/Phi = 0.318 cd/lm
A3: ## | B3: XDim | C3: YDim | D3: minXbound | E3: minYbound | F3: maxXbound | G3: maxYbound
A4: SPHEREMESH: | B4: 1 | C4: 90 | D4: 0 | E4: 0 | F4: 360 | G4: 90
A5: ## | B5: Mesh cell values
A6: =+cosn!R4 -> 0.0087262032
A7: =+cosn!R5 -> 0.026175952
A8: =+cosn!R6 -> 0.043617726
A9: =+cosn!R7 -> 0.061046215
A10: =+cosn!R8 -> 0.078456108
A11: =+cosn!R9 -> 0.095842103
A12: =+cosn!R10 -> 0.1131989
A13: =+cosn!R11 -> 0.13052122
A14: =+cosn!R12 -> 0.14780378
A15: =+cosn!R13 -> 0.16504132
A16: =+cosn!R14 -> 0.18222859
A17: =+cosn!R15 -> 0.19936034
... A41: =+cosn!R39 -> 0.58068084
A42: =+cosn!R43 -> 0.59480014
A43: =+cosn!R44 -> 0.60873825
A44: =+cosn!R45 -> 0.62249093
A45: =+cosn!R46 -> 0.636054
A46: =+cosn!R47 -> 0.64942332
A47: =+cosn!R48 -> 0.66259482
A48: =+cosn!R49 -> 0.67556448
A49: =+cosn!R50 -> 0.68832837
A50: =+cosn!R51 -> 0.70088258
A51: =+cosn!R52 -> 0.71322329
A52: =+cosn!R53 -> 0.72534675
A53: =+cosn!R54 -> 0.73724926
... A95: =+cosn!R96 -> 0.99992385
